<?xml version="1.0" encoding="UTF-8"?>
<robot xmlns:xacro="http://www.ros.org/wiki/xacro"
      xmlns:controller="http://playerstage.sourceforge.net/gazebo/xmlschema/#controller"
   name="lwr" >
   <xacro:property name="velocity_scale" value="50.0"/>
   <xacro:property name="effort_scale" value="50.0"/>

   <xacro:property name="M_PI" value="3.1415926535897931" />

   <xacro:property name="damping_factor" value="1.0"/>

   <xacro:property name="d0" value="${damping_factor*5.5}"/>
   <xacro:property name="d1" value="${damping_factor*5.5}"/>
   <xacro:property name="d2" value="${damping_factor*3.5}"/>
   <xacro:property name="d3" value="${damping_factor*3.5}"/>
   <xacro:property name="d4" value="${damping_factor*3.5}"/>
   <xacro:property name="d5" value="${damping_factor*1.1}"/>
   <xacro:property name="d6" value="${damping_factor*0.1}"/>




  <!-- Gazebo joint configuration -->

   <xacro:macro name="lwr" params="parent *origin ">

      <!-- joint between {parent} and lwr_0_link -->
      <joint name="joint_base" type="fixed">

         <xacro:insert_block name="origin" />
         <parent link="${parent}" />
         <child link="link_0" />
      </joint>
      <link name="link_0">
          <inertial>
            <origin
              xyz="-0.000638499331014356 5.02538509694617E-06 0.0482289968116927"
              rpy="0 0 0" />
            <mass
              value="1.21032454350876" />
            <inertia
              ixx="0.00262560565710656"
              ixy="-5.2754950052563E-07"
              ixz="3.77940202490646E-05"
              iyy="0.00280724642508563"
              iyz="-2.56972470148208E-07"
              izz="0.00306998250407766" />
          </inertial>
         <visual>
            <origin xyz="0 0 0" rpy="0 0 ${M_PI}" />
            <geometry>
               <mesh filename="package://lwr_description/meshes/lwr/link0.stl" />
            </geometry>
            <material name="color_j0" />
         </visual>
         <collision>
            <origin xyz="0 0 0" rpy="0 0 ${M_PI}" />
            <geometry>
               <mesh filename="package://lwr_description/meshes/lwr/link0_c2.stl" />
            </geometry>
         </collision>
      </link>
      <!-- joint between lwr_0_link and lwr_1_link -->
      <joint name="joint_0" type="revolute">

         <parent link="link_0" />
         <child link="link_1" />
         <limit lower="${-170 * M_PI / 180}" upper="${170 * M_PI / 180}" effort="${effort_scale * 200}" velocity="${velocity_scale * 112.5 * M_PI / 180}" />

         <dynamics friction="0" damping="${d0}"/>
         <origin xyz="0 0 0.102" rpy="0 0 0" />
         <axis xyz="0 0 1" />
      </joint>
      <link name="link_1">
          <inertial>
            <origin
              xyz="-6.33965437334127E-08 0.0233273473346096 0.118146290406178"
              rpy="0 0 0" />
            <mass
              value="2.30339938771869" />
            <inertia
              ixx="0.0156081163626041"
              ixy="5.97319920503909E-08"
              ixz="-1.64780770629425E-07"
              iyy="0.0153467542173805"
              iyz="0.00319168949093809"
              izz="0.00440736079943446" />
          </inertial>
         <visual>
            <origin xyz="0 0 0" rpy="0 0 ${M_PI}" />
            <geometry>
               <mesh filename="package://lwr_description/meshes/lwr/link1.stl" />
            </geometry>
            <material name="color_j1" />
         </visual>
         <collision>
            <origin xyz="0 0 0" rpy="0 0 ${M_PI}" />
            <geometry>
               <mesh filename="package://lwr_description/meshes/lwr/link1_c2.stl" />
            </geometry>
         </collision>
      </link>
      <!-- joint between lwr_1_link and lwr_2_link -->
      <joint name="joint_1" type="revolute">

         <parent link="link_1" />
         <child link="link_2" />
         <limit lower="${-120 * M_PI / 180}" upper="${120 * M_PI / 180}" effort="${effort_scale * 200}" velocity="${velocity_scale * 112.5 * M_PI / 180}" />

         <dynamics friction="0" damping="${d1}"/>
         <origin xyz="0 0.0 0.2085" rpy="0 0 0" />
         <axis xyz="0 -1 0" />
      </joint>
      <link name="link_2">
    <inertial>
      <origin
        xyz="1.26774962153076E-06 -0.032746486541291 0.0736556727355962"
        rpy="0 0 0" />
      <mass
        value="2.30343543179071" />
      <inertia
        ixx="0.0142348526057094"
        ixy="-3.73763310100809E-08"
        ixz="1.70703603169075E-07"
        iyy="0.0141319978448755"
        iyz="0.00228090337255746"
        izz="0.00424792208583136" />
    </inertial>
         <visual>
            <origin xyz="0 0 0" rpy="0 0 ${M_PI}" />
            <geometry>
               <mesh filename="package://lwr_description/meshes/lwr/link2.stl" />
            </geometry>
            <material name="color_j2" />
         </visual>
         <collision>
            <origin xyz="0 0 0" rpy="0 0 ${M_PI}" />
            <geometry>
               <mesh filename="package://lwr_description/meshes/lwr/link2_c2.stl" />
            </geometry>
           <surface>
            <friction>
              <ode>
                <mu>0.998000</mu>
                <mu2>0.998000</mu2>
              </ode>
            </friction>
          </surface>
         </collision>
      </link>
      <!-- joint between lwr_2_link and lwr_3_link -->
      <joint name="joint_2" type="revolute">

         <parent link="link_2" />
         <child link="link_3" />
         <limit lower="${-170 * M_PI / 180}" upper="${170 * M_PI / 180}" effort="${effort_scale * 100}" velocity="${velocity_scale * 112.5 * M_PI / 180}" />

         <dynamics friction="0" damping="${d2}"/>
         <origin xyz="0 0 0.1915" rpy="0 0 0" />
         <axis xyz="0 0 1" />
      </joint>
      <link name="link_3">
    <inertial>
      <origin
        xyz="-1.40921289121243E-06 -0.0233297626126898 0.11815047247629"
        rpy="0 0 0" />
      <mass
        value="2.30342143971329" />
      <inertia
        ixx="0.0156098024078732"
        ixy="4.75479645197283E-08"
        ixz="1.17852233217589E-07"
        iyy="0.0153476851366831"
        iyz="-0.00319215869825882"
        izz="0.0044071430916942" />
    </inertial>
         <visual>
            <origin xyz="0 0 0" rpy="0 0 ${M_PI}" />
            <geometry>
               <mesh filename="package://lwr_description/meshes/lwr/link3.stl" />
            </geometry>
            <material name="color_j3" />
         </visual>
         <collision>
            <origin xyz="0 0 0" rpy="0 0 ${M_PI}" />
            <geometry>
               <mesh filename="package://lwr_description/meshes/lwr/link3_c2.stl" />
            </geometry>
         </collision>
      </link>
      <!-- joint between lwr_3_link and lwr_4_link -->
      <joint name="joint_3" type="revolute">

         <parent link="link_3" />
         <child link="link_4" />
         <limit lower="${-120 * M_PI / 180}" upper="${120 * M_PI / 180}" effort="${effort_scale * 100}" velocity="${velocity_scale * 112.5 * M_PI / 180}" />

         <dynamics friction="0" damping="${d3}"/>
         <origin xyz="0 0 0.2085" rpy="0 0 0" />
         <axis xyz="0 1 0" />
      </joint>
      <link name="link_4">
    <inertial>
      <origin
        xyz="1.12239473548659E-07 0.0327442387470235 0.073658815701594"
        rpy="0 0 0" />
      <mass
        value="2.30343586527606" />
      <inertia
        ixx="0.0142336552604204"
        ixy="-5.89296043886227E-08"
        ixz="-1.568273589226E-07"
        iyy="0.0141315528954361"
        iyz="-0.00228056254422505"
        izz="0.00424816761410708" />
    </inertial>
         <visual>
            <origin xyz="0 0 0" rpy="0 0 ${M_PI}" />
            <geometry>
               <mesh filename="package://lwr_description/meshes/lwr/link4.stl" />
            </geometry>
            <material name="color_j4" />
         </visual>
         <collision>
            <origin xyz="0 0 0" rpy="0 0 ${M_PI}" />
            <geometry>
               <mesh filename="package://lwr_description/meshes/lwr/link4_c2.stl" />
            </geometry>
         </collision>
      </link>
      <!-- joint between lwr_4_link and lwr_5_link -->
      <joint name="joint_4" type="revolute">

         <parent link="link_4" />
         <child link="link_5" />
         <limit lower="${-170 * M_PI / 180}" upper="${170 * M_PI / 180}" effort="${effort_scale * 100}" velocity="${velocity_scale * 180.0 * M_PI / 180}" />

         <dynamics friction="0" damping="${d4}"/>
         <origin xyz="0 0.0 0.1915" rpy="0 0 0" />
         <axis xyz="0 0 1" />
      </joint>
      <link name="link_5">
    <inertial>
      <origin
        xyz="-6.00824789920296E-07 0.0207751869661564 0.0862053948486382"
        rpy="0 0 0" />
      <mass
        value="1.60059828363332" />
      <inertia
        ixx="0.00880806620496216"
        ixy="1.22820321842462E-07"
        ixz="-5.66844221164893E-08"
        iyy="0.00813520145401624"
        iyz="0.00261443543508601"
        izz="0.00359712267754715" />
    </inertial>
         <visual>
            <origin xyz="0 0 0" rpy="0 0 ${M_PI}" />
            <geometry>
               <mesh filename="package://lwr_description/meshes/lwr/link5.stl" />
            </geometry>
            <material name="color_j5" />
         </visual>
         <collision>
            <origin xyz="0 0 0" rpy="0 0 ${M_PI}" />
            <geometry>
               <mesh filename="package://lwr_description/meshes/lwr/link5_c2.stl" />
            </geometry>
         </collision>
      </link>
      <!-- joint between lwr_5_link and lwr_6_link -->
      <joint name="joint_5" type="revolute">

         <parent link="link_5" />
         <child link="link_6" />
         <limit lower="${-120 * M_PI / 180}" upper="${120 * M_PI / 180}" effort="${effort_scale * 30}" velocity="${velocity_scale * 112.5 * M_PI / 180}" />

         <dynamics friction="0" damping="${d5}"/>
         <origin xyz="0 0 0.1985" rpy="0 0 0" />
         <axis xyz="0 -1 0" />
      </joint>
      <link name="link_6">
    <inertial>
      <origin
        xyz="-2.64519244286276E-08 -0.00451753627467652 -0.00295324741635017"
        rpy="0 0 0" />
      <mass
        value="1.49302436988808" />
      <inertia
        ixx="0.00298541138330797"
        ixy="-3.97658663154265E-09"
        ixz="-1.71667243685877E-09"
        iyy="0.00299834927882566"
        iyz="-2.53647350791604E-05"
        izz="0.00323627047307316" />
    </inertial>
         <visual>
            <origin xyz="0 0 0" rpy="0 0 ${M_PI}" />
            <geometry>
               <mesh filename="package://lwr_description/meshes/lwr/link6.stl" />
            </geometry>
            <material name="color_j6" />
         </visual>
         <collision>
            <origin xyz="0 0 0" rpy="0 0 ${M_PI}" />
            <geometry>
               <mesh filename="package://lwr_description/meshes/lwr/link6_c2.stl" />
            </geometry>
         </collision>
      </link>
      <!-- joint between lwr_6_link and lwr_7_link -->
      <joint name="joint_6" type="revolute">

         <parent link="link_6" />
         <child link="link_7" />
         <limit lower="${-170 * M_PI / 180}" upper="${170 * M_PI / 180}" effort="${effort_scale * 30}" velocity="${velocity_scale * 112.5 * M_PI / 180}" />
         <dynamics friction="0" damping="${d6}"/>
         <origin xyz="0 0 0.078" rpy="0 0 0" />
         <axis xyz="0 0 1" />
      </joint>
      <link name="link_7">
    <inertial>
      <origin
        xyz="2.77555756156289E-17 1.11022302462516E-16 -0.015814675599801"
        rpy="0 0 0" />
      <mass
        value="0.108688241139613" />
      <inertia
        ixx="4.17908737998876E-05"
        ixy="0"
        ixz="0"
        iyy="4.17908737998876E-05"
        iyz="0"
        izz="7.00756879151782E-05" />
    </inertial>
         <visual>
            <origin xyz="0 0 0" rpy="0 0 ${M_PI}" />
            <geometry>
               <mesh filename="package://lwr_description/meshes/lwr/link7.stl" />
            </geometry>
            <material name="color_j7" />
         </visual>
         <collision>
            <origin xyz="0 0 0" rpy="0 0 ${M_PI}" />
            <geometry>
               <mesh filename="package://lwr_description/meshes/lwr/link7_c2.stl" />
            </geometry>
         </collision>
      </link>
   </xacro:macro>
</robot>
