<?xml version="1.0" ?>
<!-- =================================================================================== -->
<!-- |    This document was autogenerated by xacro from kuka_lwr.urdf.xacro            | -->
<!-- |    EDITING THIS FILE BY HAND IS NOT RECOMMENDED                                 | -->
<!-- =================================================================================== -->
<robot name="lwr" xmlns:controller="http://playerstage.sourceforge.net/gazebo/xmlschema/#controller" xmlns:xacro="http://ros.org/wiki/xacro">
  <!-- lbr-->
  <!-- generic simulator_gazebo plugins -->
  <!-- materials for visualization -->
  <material name="color_j0">
    <color rgba="1.0 0.423529411765 0.196078431373 1.0"/>
  </material>
  <material name="color_j1">
    <color rgba="1.0 0.423529411765 0.196078431373 1.0"/>
  </material>
  <material name="color_j2">
    <color rgba="1.0 0.423529411765 0.196078431373 1.0"/>
  </material>
  <material name="color_j3">
    <color rgba="1.0 0.423529411765 0.196078431373 1.0"/>
  </material>
  <material name="color_j4">
    <color rgba="1.0 0.423529411765 0.196078431373 1.0"/>
  </material>
  <material name="color_j5">
    <color rgba="1.0 0.423529411765 0.196078431373 1.0"/>
  </material>
  <material name="color_j6">
    <color rgba="0.3 0.3 0.3 1.0"/>
  </material>
  <material name="color_j7">
    <color rgba="0.7 0.7 0.7 1.0"/>
  </material>
  <!-- world + base link-->
  <link name="world"/>
  <link name="lwr/base_link"/>
  <joint name="lwr/base_joint" type="fixed">
    <parent link="world"/>
    <child link="lwr/base_link"/>
  </joint>
  <gazebo reference="lwr/base_link">
    <static>true</static>
  </gazebo>
  <!--lbr-->
  <joint name="lwr/lwr/base_link_base" type="fixed">
    <gazebo reference="lwr/lwr/base_link_base">
      <provideFeedback>true</provideFeedback>
      <implicitSpringDamper>true</implicitSpringDamper>
    </gazebo>
    <origin rpy="0 0 2.09439510239" xyz="0 0 0.01"/>
    <parent link="lwr/base_link"/>
    <child link="lwr/lwr_0_link"/>
  </joint>
  <link name="lwr/lwr_0_link">
    <inertial>
      <origin rpy="0 0 0" xyz="0 0 0"/>
      <mass value="3.65"/>
      <inertia ixx="0.00805112828804" ixy="0" ixz="0" iyy="0.00845152236845" iyz="0" izz="0.00863585824764"/>
    </inertial>
    <visual>
      <origin rpy="0 0 3.14159265359" xyz="0 0 0"/>
      <geometry>
        <mesh filename="package://lwr_description/meshes/lwr/link0.stl"/>
      </geometry>
      <material name="color_j0"/>
    </visual>
    <collision>
      <origin rpy="0 0 3.14159265359" xyz="0 0 0"/>
      <geometry>
        <mesh filename="package://lwr_description/meshes/lwr/link0.dae"/>
      </geometry>
      <surface>
        <friction>
          <ode>
            <mu>0.998000</mu>
            <mu2>0.998000</mu2>
            <fdir1>0.000000 0.000000 0.000000</fdir1>
            <slip1>0.000000</slip1>
            <slip2>0.000000</slip2>
          </ode>
        </friction>
        <bounce>
          <restitution_coefficient>0.000000</restitution_coefficient>
          <threshold>100000.000000</threshold>
        </bounce>
        <contact>
          <ode>
            <soft_cfm>0.000000</soft_cfm>
            <soft_erp>0.200000</soft_erp>
            <kp>100000.000000</kp>
            <kd>1.000000</kd>
            <max_vel>100.000000</max_vel>
            <min_depth>0.001000</min_depth>
          </ode>
        </contact>
      </surface>
    </collision>
  </link>
  <joint name="lwr/lwr_0_joint" type="revolute">
    <gazebo reference="lwr/lwr_0_joint">
      <provideFeedback>true</provideFeedback>
      <implicitSpringDamper>true</implicitSpringDamper>
    </gazebo>
    <parent link="lwr/lwr_0_link"/>
    <child link="lwr/lwr_1_link"/>
    <limit effort="200.0" lower="-2.96705972839" upper="2.96705972839" velocity="1.96349540849"/>
    <dynamics damping="1.0" friction="0.0"/>
    <origin rpy="0 0 0" xyz="0 0 0.103"/>
    <axis xyz="0 0 1"/>
  </joint>
  <link name="lwr/lwr_1_link">
    <inertial>
      <origin rpy="0.239538165056 0.00537995201801 0.0492155584082" xyz="2.1826998880744087e-05 -0.021623840412335664 -0.07915171924289198"/>
      <mass value="2.0"/>
      <inertia ixx="0.0129545076394" ixy="0" ixz="0" iyy="0.0128178432409" iyz="0" izz="0.00442072765916"/>
    </inertial>
    <visual>
      <origin rpy="0 0 3.14159265359" xyz="0 0 0"/>
      <geometry>
        <mesh filename="package://lwr_description/meshes/lwr/link1.stl"/>
      </geometry>
      <material name="color_j1"/>
    </visual>
    <collision>
      <origin rpy="0 0 3.14159265359" xyz="0 0 0"/>
      <geometry>
        <mesh filename="package://lwr_description/meshes/lwr/link1.dae"/>
      </geometry>
      <surface>
        <friction>
          <ode>
            <mu>0.998000</mu>
            <mu2>0.998000</mu2>
            <fdir1>0.000000 0.000000 0.000000</fdir1>
            <slip1>0.000000</slip1>
            <slip2>0.000000</slip2>
          </ode>
        </friction>
        <bounce>
          <restitution_coefficient>0.000000</restitution_coefficient>
          <threshold>100000.000000</threshold>
        </bounce>
        <contact>
          <ode>
            <soft_cfm>0.000000</soft_cfm>
            <soft_erp>0.200000</soft_erp>
            <kp>100000.000000</kp>
            <kd>1.000000</kd>
            <max_vel>100.000000</max_vel>
            <min_depth>0.001000</min_depth>
          </ode>
        </contact>
      </surface>
    </collision>
  </link>
  <joint name="lwr/lwr_1_joint" type="revolute">
    <gazebo reference="lwr/lwr_1_joint">
      <provideFeedback>true</provideFeedback>
      <implicitSpringDamper>true</implicitSpringDamper>
    </gazebo>
    <parent link="lwr/lwr_1_link"/>
    <child link="lwr/lwr_2_link"/>
    <limit effort="200.0" lower="-2.09439510239" upper="2.09439510239" velocity="1.96349540849"/>
    <dynamics damping="1.0" friction="0.0"/>
    <origin rpy="0 0 0" xyz="0 0 0.2105"/>
    <axis xyz="0 -1 0"/>
  </joint>
  <link name="lwr/lwr_2_link">
    <inertial>
      <origin rpy="0.252444092172 -0.0167820344187 0.0575928285281" xyz="-0.0010097053542516513 0.028478464648332931 0.082033627936009448"/>
      <mass value="2.0"/>
      <inertia ixx="0.0132950018592" ixy="0" ixz="0" iyy="0.0131003199685" iyz="0" izz="0.0044657387969"/>
    </inertial>
    <visual>
      <origin rpy="0 0 3.14159265359" xyz="0 0 0"/>
      <geometry>
        <mesh filename="package://lwr_description/meshes/lwr/link2.stl"/>
      </geometry>
      <material name="color_j2"/>
    </visual>
    <collision>
      <origin rpy="0 0 3.14159265359" xyz="0 0 0"/>
      <geometry>
        <mesh filename="package://lwr_description/meshes/lwr/link2.dae"/>
      </geometry>
      <surface>
        <friction>
          <ode>
            <mu>0.998000</mu>
            <mu2>0.998000</mu2>
          </ode>
        </friction>
      </surface>
    </collision>
  </link>
  <joint name="lwr/lwr_2_joint" type="revolute">
    <gazebo reference="lwr/lwr_2_joint">
      <provideFeedback>true</provideFeedback>
      <implicitSpringDamper>true</implicitSpringDamper>
    </gazebo>
    <parent link="lwr/lwr_2_link"/>
    <child link="lwr/lwr_3_link"/>
    <limit effort="100.0" lower="-2.96705972839" upper="2.96705972839" velocity="1.96349540849"/>
    <dynamics damping="1.0" friction="0.0"/>
    <origin rpy="0 0 0" xyz="0 0 0.192"/>
    <axis xyz="0 0 1"/>
  </joint>
  <link name="lwr/lwr_3_link">
    <inertial>
      <origin rpy="-0.211279484805 -0.0186487662306 -0.00721347462905" xyz="-0.00068512472584392442 0.022787627643261723 -0.078806475454300237"/>
      <mass value="2.0"/>
      <inertia ixx="0.0127763513867" ixy="0" ixz="0" iyy="0.0128011372133" iyz="0" izz="0.0043627376553"/>
    </inertial>
    <visual>
      <origin rpy="0 0 3.14159265359" xyz="0 0 0"/>
      <geometry>
        <mesh filename="package://lwr_description/meshes/lwr/link3.stl"/>
      </geometry>
      <material name="color_j3"/>
    </visual>
    <collision>
      <origin rpy="0 0 3.14159265359" xyz="0 0 0"/>
      <geometry>
        <mesh filename="package://lwr_description/meshes/lwr/link3.dae"/>
      </geometry>
      <surface>
        <friction>
          <ode>
            <mu>0.998000</mu>
            <mu2>0.998000</mu2>
            <fdir1>0.000000 0.000000 0.000000</fdir1>
            <slip1>0.000000</slip1>
            <slip2>0.000000</slip2>
          </ode>
        </friction>
        <bounce>
          <restitution_coefficient>0.000000</restitution_coefficient>
          <threshold>100000.000000</threshold>
        </bounce>
        <contact>
          <ode>
            <soft_cfm>0.000000</soft_cfm>
            <soft_erp>0.200000</soft_erp>
            <kp>100000.000000</kp>
            <kd>1.000000</kd>
            <max_vel>100.000000</max_vel>
            <min_depth>0.001000</min_depth>
          </ode>
        </contact>
      </surface>
    </collision>
  </link>
  <joint name="lwr/lwr_3_joint" type="revolute">
    <gazebo reference="lwr/lwr_3_joint">
      <provideFeedback>true</provideFeedback>
      <implicitSpringDamper>true</implicitSpringDamper>
    </gazebo>
    <parent link="lwr/lwr_3_link"/>
    <child link="lwr/lwr_4_link"/>
    <limit effort="100.0" lower="-2.09439510239" upper="2.09439510239" velocity="1.96349540849"/>
    <dynamics damping="1.0" friction="0.0"/>
    <origin rpy="0 0 0" xyz="0 0.003 0.21"/>
    <axis xyz="0 1 0"/>
  </joint>
  <link name="lwr/lwr_4_link">
    <inertial>
      <origin rpy="0.259090664398 -0.00225330262131 0.0469419954367" xyz="-0.00025120620404353643 0.027040543208881447 0.082599870266635594"/>
      <mass value="2.0"/>
      <inertia ixx="0.0132276730313" ixy="0" ixz="0" iyy="0.0130734228464" iyz="0" izz="0.00439977729281"/>
    </inertial>
    <visual>
      <origin rpy="0 0 3.14159265359" xyz="0 0 0"/>
      <geometry>
        <mesh filename="package://lwr_description/meshes/lwr/link4.stl"/>
      </geometry>
      <material name="color_j4"/>
    </visual>
    <collision>
      <origin rpy="0 0 3.14159265359" xyz="0 0 0"/>
      <geometry>
        <mesh filename="package://lwr_description/meshes/lwr/link4.dae"/>
      </geometry>
      <surface>
        <friction>
          <ode>
            <mu>0.998000</mu>
            <mu2>0.998000</mu2>
            <fdir1>0.000000 0.000000 0.000000</fdir1>
            <slip1>0.000000</slip1>
            <slip2>0.000000</slip2>
          </ode>
        </friction>
        <bounce>
          <restitution_coefficient>0.000000</restitution_coefficient>
          <threshold>100000.000000</threshold>
        </bounce>
        <contact>
          <ode>
            <soft_cfm>0.000000</soft_cfm>
            <soft_erp>0.200000</soft_erp>
            <kp>100000.000000</kp>
            <kd>1.000000</kd>
            <max_vel>100.000000</max_vel>
            <min_depth>0.001000</min_depth>
          </ode>
        </contact>
      </surface>
    </collision>
  </link>
  <joint name="lwr/lwr_4_joint" type="revolute">
    <gazebo reference="lwr/lwr_4_joint">
      <provideFeedback>true</provideFeedback>
      <implicitSpringDamper>true</implicitSpringDamper>
    </gazebo>
    <parent link="lwr/lwr_4_link"/>
    <child link="lwr/lwr_5_link"/>
    <limit effort="100.0" lower="-2.96705972839" upper="2.96705972839" velocity="3.14159265359"/>
    <dynamics damping="1.0" friction="0.0"/>
    <origin rpy="0 0 0" xyz="0 0 0.193"/>
    <axis xyz="0 0 1"/>
  </joint>
  <link name="lwr/lwr_5_link">
    <inertial>
      <origin rpy="-0.399346437469 -0.0238815557936 0.011018430381" xyz="-7.2951660343995983e-05 0.034300558520003806 -0.082836449419419589"/>
      <mass value="2.0"/>
      <inertia ixx="0.0124407882151" ixy="0" ixz="0" iyy="0.0124710412724" iyz="0" izz="0.00438005667842"/>
    </inertial>
    <visual>
      <origin rpy="0 0 3.14159265359" xyz="0 0 0"/>
      <geometry>
        <mesh filename="package://lwr_description/meshes/lwr/link5.stl"/>
      </geometry>
      <material name="color_j5"/>
    </visual>
    <collision>
      <origin rpy="0 0 3.14159265359" xyz="0 0 0"/>
      <geometry>
        <mesh filename="package://lwr_description/meshes/lwr/link5.dae"/>
      </geometry>
      <surface>
        <friction>
          <ode>
            <mu>0.998000</mu>
            <mu2>0.998000</mu2>
            <fdir1>0.000000 0.000000 0.000000</fdir1>
            <slip1>0.000000</slip1>
            <slip2>0.000000</slip2>
          </ode>
        </friction>
        <bounce>
          <restitution_coefficient>0.000000</restitution_coefficient>
          <threshold>100000.000000</threshold>
        </bounce>
        <contact>
          <ode>
            <soft_cfm>0.000000</soft_cfm>
            <soft_erp>0.200000</soft_erp>
            <kp>100000.000000</kp>
            <kd>1.000000</kd>
            <max_vel>100.000000</max_vel>
            <min_depth>0.001000</min_depth>
          </ode>
        </contact>
      </surface>
    </collision>
  </link>
  <joint name="lwr/lwr_5_joint" type="revolute">
    <gazebo reference="lwr/lwr_5_joint">
      <provideFeedback>true</provideFeedback>
      <implicitSpringDamper>true</implicitSpringDamper>
    </gazebo>
    <parent link="lwr/lwr_5_link"/>
    <child link="lwr/lwr_6_link"/>
    <limit effort="30.0" lower="-2.09439510239" upper="2.09439510239" velocity="1.96349540849"/>
    <dynamics damping="1.0" friction="0.0"/>
    <origin rpy="0 0 0" xyz="0 0 0.2"/>
    <axis xyz="0 -1 0"/>
  </joint>
  <link name="lwr/lwr_6_link">
    <inertial>
      <origin rpy="0.0273247151986 -0.416007068876 -0.06463859276" xyz="0.0033265785100209406 -0.00025060639771109469 0.0006250581115164501"/>
      <mass value="2.0"/>
      <inertia ixx="0.00284169077177" ixy="0" ixz="0" iyy="0.00298256896714" iyz="0" izz="0.00296892557443"/>
    </inertial>
    <visual>
      <origin rpy="0 0 3.14159265359" xyz="0 0 0"/>
      <geometry>
        <mesh filename="package://lwr_description/meshes/lwr/link6.stl"/>
      </geometry>
      <material name="color_j6"/>
    </visual>
    <collision>
      <origin rpy="0 0 3.14159265359" xyz="0 0 0"/>
      <geometry>
        <mesh filename="package://lwr_description/meshes/lwr/link6.dae"/>
      </geometry>
      <surface>
        <friction>
          <ode>
            <mu>0.998000</mu>
            <mu2>0.998000</mu2>
            <fdir1>0.000000 0.000000 0.000000</fdir1>
            <slip1>0.000000</slip1>
            <slip2>0.000000</slip2>
          </ode>
        </friction>
        <bounce>
          <restitution_coefficient>0.000000</restitution_coefficient>
          <threshold>100000.000000</threshold>
        </bounce>
        <contact>
          <ode>
            <soft_cfm>0.000000</soft_cfm>
            <soft_erp>0.200000</soft_erp>
            <kp>100000.000000</kp>
            <kd>1.000000</kd>
            <max_vel>100.000000</max_vel>
            <min_depth>0.001000</min_depth>
          </ode>
        </contact>
      </surface>
    </collision>
  </link>
  <joint name="lwr/lwr_6_joint" type="revolute">
    <gazebo reference="lwr/lwr_6_joint">
      <provideFeedback>true</provideFeedback>
      <implicitSpringDamper>true</implicitSpringDamper>
    </gazebo>
    <parent link="lwr/lwr_6_link"/>
    <child link="lwr/lwr_7_link"/>
    <limit effort="30.0" lower="-2.96705972839" upper="2.96705972839" velocity="1.96349540849"/>
    <dynamics damping="1.0" friction="0.0"/>
    <origin rpy="0 0 0" xyz="0 0 0.079"/>
    <axis xyz="0 0 1"/>
  </joint>
  <link name="lwr/lwr_7_link">
    <inertial>
      <origin rpy="-0.00140457256351 -0.0113238487485 -0.621939623896" xyz="-1.0508863000830793e-05 0.00049391465901896074 0.062507829615577853"/>
      <mass value="0.350"/>
      <inertia ixx="0.000581502716972" ixy="0" ixz="0" iyy="0.000584472283068" iyz="0" izz="0.000968983240391"/>
    </inertial>
    <visual>
      <origin rpy="0 0 3.14159265359" xyz="0 0 0"/>
      <geometry>
        <mesh filename="package://lwr_description/meshes/lwr/link7.stl"/>
      </geometry>
      <material name="color_j7"/>
    </visual>
    <collision>
      <origin rpy="0 0 3.14159265359" xyz="0 0 0"/>
      <geometry>
        <mesh filename="package://lwr_description/meshes/lwr/link7.dae"/>
      </geometry>
      <surface>
        <friction>
          <ode>
            <mu>0.998000</mu>
            <mu2>0.998000</mu2>
            <fdir1>0.000000 0.000000 0.000000</fdir1>
            <slip1>0.000000</slip1>
            <slip2>0.000000</slip2>
          </ode>
        </friction>
        <bounce>
          <restitution_coefficient>0.000000</restitution_coefficient>
          <threshold>100000.000000</threshold>
        </bounce>
        <contact>
          <ode>
            <soft_cfm>0.000000</soft_cfm>
            <soft_erp>0.200000</soft_erp>
            <kp>100000.000000</kp>
            <kd>1.000000</kd>
            <max_vel>100.000000</max_vel>
            <min_depth>0.001000</min_depth>
          </ode>
        </contact>
      </surface>
    </collision>
  </link>
  <link name="lwr/kuka_polaris"/>
  <joint name="lwr/tool_joint" type="fixed">
    <parent link="lwr/lwr_7_link"/>
    <child link="lwr/kuka_polaris"/>
    <origin rpy="0 0 0" xyz="0 0 0.055"/>
  </joint>
  <gazebo>
    <plugin filename="librtt_gazebo_deployer.so" name="rtt_gazebo">
      <component>
        <package>rtt_lwr_gazebo</package>
        <type>LWRGazeboComponent</type>
        <name>lwr_gazebo</name>
      </component>
      <!--orocosScript><filename>$(arg ops_script)</filename></orocosScript-->
      <luaScript>
        <filename>none</filename>
      </luaScript>
    </plugin>
  </gazebo>
  <gazebo reference="lwr/lwr_0_link">
    <gravity>true</gravity>
    <material>Gazebo/Orange</material>
  </gazebo>
  <gazebo reference="lwr/lwr_1_link">
    <gravity>true</gravity>
    <material>Gazebo/Orange</material>
  </gazebo>
  <gazebo reference="lwr/lwr_2_link">
    <gravity>true</gravity>
    <material>Gazebo/Orange</material>
  </gazebo>
  <gazebo reference="lwr/lwr_3_link">
    <gravity>true</gravity>
    <material>Gazebo/Orange</material>
  </gazebo>
  <gazebo reference="lwr/lwr_4_link">
    <gravity>true</gravity>
    <material>Gazebo/Orange</material>
  </gazebo>
  <gazebo reference="lwr/lwr_5_link">
    <gravity>true</gravity>
    <material>Gazebo/Orange</material>
  </gazebo>
  <gazebo reference="lwr/lwr_6_link">
    <gravity>true</gravity>
    <material>Gazebo/Grey</material>
  </gazebo>
  <gazebo reference="lwr/lwr_7_link">
    <gravity>true</gravity>
    <material>Gazebo/Grey</material>
  </gazebo>
  <transmission name="lwr/lwr_0_trans">
    <type>transmission_interface/SimpleTransmission</type>
    <joint name="lwr/lwr_0_joint"/>
    <actuator name="lwr/lwr_0_motor">
      <hardwareInterface>EffortJointInterface</hardwareInterface>
      <mechanicalReduction>1</mechanicalReduction>
    </actuator>
  </transmission>
  <transmission name="lwr/lwr_1_trans">
    <type>transmission_interface/SimpleTransmission</type>
    <joint name="lwr/lwr_1_joint"/>
    <actuator name="lwr/lwr_1_motor">
      <hardwareInterface>EffortJointInterface</hardwareInterface>
      <mechanicalReduction>1</mechanicalReduction>
    </actuator>
  </transmission>
  <transmission name="lwr/lwr_2_trans">
    <type>transmission_interface/SimpleTransmission</type>
    <joint name="lwr/lwr_2_joint"/>
    <actuator name="lwr/lwr_2_motor">
      <hardwareInterface>EffortJointInterface</hardwareInterface>
      <mechanicalReduction>1</mechanicalReduction>
    </actuator>
  </transmission>
  <transmission name="lwr/lwr_3_trans">
    <type>transmission_interface/SimpleTransmission</type>
    <joint name="lwr/lwr_3_joint"/>
    <actuator name="lwr/lwr_3_motor">
      <hardwareInterface>EffortJointInterface</hardwareInterface>
      <mechanicalReduction>1</mechanicalReduction>
    </actuator>
  </transmission>
  <transmission name="lwr/lwr_4_trans">
    <type>transmission_interface/SimpleTransmission</type>
    <joint name="lwr/lwr_4_joint"/>
    <actuator name="lwr/lwr_4_motor">
      <hardwareInterface>EffortJointInterface</hardwareInterface>
      <mechanicalReduction>1</mechanicalReduction>
    </actuator>
  </transmission>
  <transmission name="lwr/lwr_5_trans">
    <type>transmission_interface/SimpleTransmission</type>
    <joint name="lwr/lwr_5_joint"/>
    <actuator name="lwr/lwr_5_motor">
      <hardwareInterface>EffortJointInterface</hardwareInterface>
      <mechanicalReduction>1</mechanicalReduction>
    </actuator>
  </transmission>
  <transmission name="lwr/lwr_6_trans">
    <type>transmission_interface/SimpleTransmission</type>
    <joint name="lwr/lwr_6_joint"/>
    <actuator name="lwr/lwr_6_motor">
      <hardwareInterface>EffortJointInterface</hardwareInterface>
      <mechanicalReduction>1</mechanicalReduction>
    </actuator>
  </transmission>
</robot>
